Workbook
Name SegmentaçãodeDados_Mês: #N/A

Sheet Contas_a_Pagar
B5: Descrição | C5: Janeiro | D5: Fevereiro | E5: Março | F5: Abril | G5: Maio | H5: Junho | I5: Julho | J5: Agosto | K5: Setembro | L5: Outubro | M5: Novembro | N5: Dezembro | O5: Total Anual
B6: Custos Operacionais
B7: Manutenção de maquinas | C7: 3500 | D7: 3500 | E7: 3500 | F7: 3500 | G7: 3500 | H7: 3500 | I7: 3500 | J7: 3500 | K7: 3500 | L7: 3500 | M7: 3500 | N7: 3500 | O7: =SUM(C7:N7) -> 42000
B8: Energia eletrica | C8: 12000 | D8: 12000 | E8: 12000 | F8: 12000 | G8: 12000 | H8: 12000 | I8: 12000 | J8: 12000 | K8: 12000 | L8: 12000 | M8: 12000 | N8: 12000 | O8: =SUM(C8:N8) -> 144000
B9: Agua | C9: 2700 | D9: 2700 | E9: 2700 | F9: 2700 | G9: 2700 | H9: 2700 | I9: 2700 | J9: 2700 | K9: 2700 | L9: 2700 | M9: 2700 | N9: 2700 | O9: =SUM(C9:N9) -> 32400
B10: Roupas e equip.Seg | C10: 4000 | D10: 1000 | E10: 0 | F10: 0 | G10: 0 | H10: 0 | I10: 0 | J10: 0 | K10: 0 | L10: 0 | M10: 0 | N10: 0 | O10: =SUM(C10:N10) -> 5000
B11: Insumos/Materia prima | C11: 120000 | D11: 30000 | E11: 120000 | F11: 4000 | G11: 32000 | H11: 28000 | I11: 56000 | J11: 76000 | K11: 45000 | L11: 36700 | M11: 123000 | N11: 143000 | O11: =SUM(C11:N11) -> 813700
B12: Mercadorias para revenda | C12: 23000 | D12: 3000 | E12: 12500 | F12: 13700 | G12: 14200 | H12: 11860 | I12: 13900 | J12: 16870 | K12: 14567 | L12: 1548 | M12: 15387 | N12: 15487 | O12: =SUM(C12:N12) -> 156019
B13: Materiais para consumo | C13: 2000 | D13: 2000 | E13: 2000 | F13: 2000 | G13: 2000 | H13: 2000 | I13: 2000 | J13: 2000 | K13: 2000 | L13: 2000 | M13: 2000 | N13: 2000 | O13: =SUM(C13:N13) -> 24000
B14: Ativo imobilizado | C14: 45000 | D14: 45000 | E14: 45000 | F14: 45000 | G14: 45000 | H14: 45000 | I14: 45000 | J14: 45000 | K14: 45000 | L14: 45000 | M14: 45000 | N14: 45000 | O14: =SUM(C14:N14) -> 540000
B15: Reformas/Manutenção Predial | C15: 20000 | D15: 20000 | E15: 20000 | F15: 20000 | G15: 20000 | H15: 20000 | I15: 20000 | J15: 20000 | K15: 20000 | L15: 20000 | M15: 20000 | N15: 20000 | O15: =SUM(C15:N15) -> 240000
B16: Frete | C16: 12000 | D16: 356346 | E16: 12000 | F16: 12000 | G16: 12000 | H16: 12000 | I16: 12000 | J16: 12000 | K16: 12000 | L16: 12000 | M16: 12000 | N16: 12000 | O16: =SUM(C16:N16) -> 488346
B17: Outros Custos Operacionais | C17: 1000 | D17: 1000 | E17: 1000 | F17: 1000 | G17: 1000 | H17: 1000 | I17: 1000 | J17: 1000 | K17: 1000 | L17: 1000 | M17: 1000 | N17: 1000 | O17: =SUM(C17:N17) -> 12000
B18: Sub-Total | C18: =SUM(C7:C17) -> 245200 | D18: =SUM(D7:D17) -> 476546 | E18: =SUM(E7:E17) -> 230700 | F18: =SUM(F7:F17) -> 115900 | G18: =SUM(G7:G17) -> 144400 | H18: =SUM(H7:H17) -> 138060 | I18: =SUM(I7:I17) -> 168100 | J18: =SUM(J7:J17) -> 191070 | ... N18: =SUM(N7:N17) -> 256687 | O18: =SUM(C18:N18) -> 2497465
B19: Custos Administrativos
B20: Materiais de escritorio | C20: 1143 | D20: 4534 | E20: 324 | F20: 342 | G20: 535 | H20: 124 | I20: 68 | J20: 3400 | K20: 0 | L20: 0 | M20: 0 | N20: 534 | O20: =SUM(C20:N20) -> 11004
B21: Impostos | C21: 45000 | D21: 64000 | E21: 64000 | F21: 64000 | G21: 64000 | H21: 45000 | I21: 64000 | J21: 45000 | K21: 45000 | L21: 64000 | M21: 45000 | N21: 64000 | O21: =SUM(C21:N21) -> 673000
B22: Funcionários | C22: 250000 | D22: 250000 | E22: 250000 | F22: 250000 | G22: 250000 | H22: 250000 | I22: 250000 | J22: 250000 | K22: 250000 | L22: 250000 | M22: 250000 | N22: 250000 | O22: =SUM(C22:N22) -> 3000000
B23: Outros custos administrativos | C23: 900 | D23: 1200 | E23: 3400 | F23: 1234 | G23: 1442 | H23: 5453 | I23: 113 | J23: 5452 | K23: 6453 | L23: 3422 | M23: 654 | N23: 342 | O23: =SUM(C23:N23) -> 30065
B24: Sub-Total | C24: =SUM(C20:C23) -> 297043 | D24: =SUM(D20:D23) -> 319734 | E24: =SUM(E20:E23) -> 317724 | F24: =SUM(F20:F23) -> 315576 | G24: =SUM(G20:G23) -> 315977 | H24: =SUM(H20:H23) -> 300577 | I24: =SUM(I20:I23) -> 314181 | J24: =SUM(J20:J23) -> 303852 | ... O24: =SUM(O20:O23) -> 3714069
B25: Investimentos
B26: Gastos com investimentos | C26: 12341 | D26: 2342 | E26: 4234 | F26: 243 | G26: 53 | H26: 24432 | I26: 234 | J26: 242 | K26: 3 | L26: 234 | M26: 234 | N26: 234 | O26: =SUM(C26:N26) -> 44826
B27: Sub-Total | C27: =SUM(C26) -> 12341 | D27: =SUM(D26) -> 2342 | E27: =SUM(E26) -> 4234 | F27: =SUM(F26) -> 243 | G27: =SUM(G26) -> 53 | H27: =SUM(H26) -> 24432 | I27: =SUM(I26) -> 234 | J27: =SUM(J26) -> 242 | ... O27: =SUM(O26) -> 44826
B28: Total | C28: =C18+C24+C27 -> 554584 | D28: =D27+D24+D18 -> 798622 | E28: =E27+E24+E18 -> 552658 | F28: =F27+F24+F18 -> 431719 | G28: =G27+G24+G18 -> 460430 | H28: =H27+H24+H18 -> 463069 | I28: =I27+I24+I18 -> 482515 | J28: =J27+J24+J18 -> 495164 | K28: =K27+K24+K18 -> 459223 | ... N28: =N27+N24+N18 -> 571797 | O28: =SUM(C28:N28) -> 6256360

Sheet Contas_a_Receber
C5: Janeiro | D5: Fevereiro | E5: Março | F5: Abril | G5: Maio | H5: Junho | I5: Julho | J5: Agosto | K5: Setembro | L5: Outubro | M5: Novembro | N5: Dezembro | O5: Total Anual
B6: Vendas
B7: Revenda | C7: 659000 | D7: 34346 | E7: 32420 | F7: 235000 | G7: 3400 | H7: 235000 | I7: 32420 | J7: 235000 | K7: 235000 | L7: 32420 | M7: 235000 | N7: 235000 | O7: =SUM(C7:N7) -> 2204006
B8: Produtos de fabricação propria | C8: 890000 | D8: 124000 | E8: 345000 | F8: 654400 | G8: 75474 | H8: 654400 | I8: 345000 | J8: 654400 | K8: 654400 | L8: 345000 | M8: 654400 | N8: 654400 | O8: =SUM(C8:N8) -> 6050874
B9: Aluguel de Maquinas | G9: 744
B10: Venda de Ativo | C10: 0 | E10: 120000 | O10: =SUM(C10:N10) -> 120000
B11: Sub-Total | C11: =SUM(C7:C10) -> 1549000 | D11: =SUM(D7:D10) -> 158346 | E11: =SUM(E7:E10) -> 497420 | F11: =SUM(F7:F10) -> 889400 | G11: =SUM(G7:G10) -> 79618 | H11: =SUM(H7:H10) -> 889400 | I11: =SUM(I7:I10) -> 377420 | J11: =SUM(J7:J10) -> 889400 | ... O11: =SUM(O7:O10) -> 8374880
B12: Prestação de Serviços
B13: Serviços prestados | C13: 12000 | D13: 1231 | E13: 34000 | F13: 34500 | G13: 32000 | H13: 65000 | I13: 65000 | J13: 65000 | K13: 34000 | L13: 65000 | M13: 65000 | N13: 65000 | O13: =SUM(C13:N13) -> 537731
B14: Sub-Total | C14: =SUM(C13) -> 12000 | D14: =SUM(D13) -> 1231 | E14: =SUM(E13) -> 34000 | F14: =SUM(F13) -> 34500 | G14: =SUM(G13) -> 32000 | H14: =SUM(H13) -> 65000 | I14: =SUM(I13) -> 65000 | J14: =SUM(J13) -> 65000 | ... O14: =SUM(O13) -> 537731
B15: Investimentos/Aplicações Financeiras
B16: Aplicações Financeiras | C16: 4367 | D16: 4780 | E16: 4780 | F16: 4780 | G16: 4780 | H16: 5100 | I16: 5100 | J16: 5100 | K16: 5340 | L16: 5340 | M16: 5340 | N16: 5600 | O16: =SUM(C16:N16) -> 60407
B17: Royaltes | C17: 0 | D17: 0 | E17: 0 | F17: 0 | G17: 0 | H17: 0 | I17: 0 | J17: 0 | K17: 0 | L17: 0 | M17: 0 | N17: 340000 | O17: =SUM(C17:N17) -> 340000
B18: Direitos autorais | C18: 0 | D18: 0 | E18: 0 | F18: 0 | G18: 0 | H18: 0 | I18: 0 | J18: 0 | K18: 0 | L18: 0 | M18: 0 | N18: 0 | O18: =SUM(C18:N18) -> 0
B19: Sub-Total | C19: =SUM(C16:C18) -> 4367 | D19: =SUM(D16:D18) -> 4780 | E19: =SUM(E16:E18) -> 4780 | F19: =SUM(F16:F18) -> 4780 | G19: =SUM(G16:G18) -> 4780 | H19: =SUM(H16:H18) -> 5100 | I19: =SUM(I16:I18) -> 5100 | J19: =SUM(J16:J18) -> 5100 | ... O19: =SUM(O16:O18) -> 400407
B20: Total | C20: =C11+C14+C19 -> 1565367 | D20: =D11+D14+D19 -> 164357 | E20: =E11+E14+E19 -> 536200 | F20: =F11+F14+F19 -> 928680 | G20: =G11+G14+G19 -> 116398 | H20: =H11+H14+H19 -> 959500 | I20: =I11+I14+I19 -> 447520 | J20: =J11+J14+J19 -> 959500 | ... O20: =O11+O14+O19 -> 9313018

Sheet Fluxo_de_Caixa
B5: Mês | C5: Entradas | D5: Saídas | E5: Saldo
B6: Janeiro | C6: =Contas_a_Receber!C20 -> 1565367 | D6: =Contas_a_Pagar!C28 -> 554584 | E6: =Tabela3[[#This Row],[Entradas]]-Tabela3[[#This Row],[Saídas]] -> 1010783
B7: Fevereiro | C7: =Contas_a_Receber!D20 -> 164357 | D7: =Contas_a_Pagar!D28 -> 798622 | E7: =E6+Tabela3[[#This Row],[Entradas]]-Tabela3[[#This Row],[Saídas]] -> 376518
B8: Março | C8: =Contas_a_Receber!E20 -> 536200 | D8: =Contas_a_Pagar!E28 -> 552658 | E8: =E7+Tabela3[[#This Row],[Entradas]]-Tabela3[[#This Row],[Saídas]] -> 360060
B9: Abril | C9: =Contas_a_Receber!F20 -> 928680 | D9: =Contas_a_Pagar!F28 -> 431719 | E9: =E8+Tabela3[[#This Row],[Entradas]]-Tabela3[[#This Row],[Saídas]] -> 857021
B10: Maio | C10: =Contas_a_Receber!G20 -> 116398 | D10: =Contas_a_Pagar!G28 -> 460430 | E10: =E9+Tabela3[[#This Row],[Entradas]]-Tabela3[[#This Row],[Saídas]] -> 512989
B11: Junho | C11: =Contas_a_Receber!H20 -> 959500 | D11: =Contas_a_Pagar!H28 -> 463069 | E11: =E10+Tabela3[[#This Row],[Entradas]]-Tabela3[[#This Row],[Saídas]] -> 1009420
B12: Julho | C12: =Contas_a_Receber!I20 -> 447520 | D12: =Contas_a_Pagar!I28 -> 482515 | E12: =E11+Tabela3[[#This Row],[Entradas]]-Tabela3[[#This Row],[Saídas]] -> 974425
B13: Agosto | C13: =Contas_a_Receber!J20 -> 959500 | D13: =Contas_a_Pagar!J28 -> 495164 | E13: =E12+Tabela3[[#This Row],[Entradas]]-Tabela3[[#This Row],[Saídas]] -> 1438761
B14: Setembro | C14: =Contas_a_Receber!K20 -> 928740 | D14: =Contas_a_Pagar!K28 -> 459223 | E14: =E13+Tabela3[[#This Row],[Entradas]]-Tabela3[[#This Row],[Saídas]] -> 1908278
B15: Outubro | C15: =Contas_a_Receber!L20 -> 447760 | D15: =Contas_a_Pagar!L28 -> 454104 | E15: =E14+Tabela3[[#This Row],[Entradas]]-Tabela3[[#This Row],[Saídas]] -> 1901934
B16: Novembro | C16: =Contas_a_Receber!M20 -> 959740 | D16: =Contas_a_Pagar!M28 -> 532475 | E16: =E15+Tabela3[[#This Row],[Entradas]]-Tabela3[[#This Row],[Saídas]] -> 2329199
B17: Dezembro | C17: =Contas_a_Receber!N20 -> 1300000 | D17: =Contas_a_Pagar!N28 -> 571797 | E17: =E16+Tabela3[[#This Row],[Entradas]]-Tabela3[[#This Row],[Saídas]] -> 3057402
B18: TOTAL | C18: =SUM(C6:C17) -> 9313762 | D18: =SUM(D6:D17) -> 6256360 | E18: =E17 -> 3057402

Sheet DRE_Simplificada
C5: Valores
B6: Receita Bruta Operacional | C6: =Contas_a_Receber!O7+Contas_a_Receber!O8+Contas_a_Receber!O14 -> 8792611
B7: (-) Custo Operacionais | C7: =Contas_a_Pagar!O18 -> 2497465
B8: Lucro Bruto | C8: =C6-C7 -> 6295146
B9: (-) Despesas Administrativas | C9: =Contas_a_Pagar!O24 -> 3714069
B10: Resultado Operacional | C10: =C8-C9 -> 2581077
B11: (+) Receitas Financeiras | C11: =Contas_a_Receber!O19 -> 400407
B12: (-) Despesas Financeiras | C12: 0
B13: Resultados Financeiros | C13: =C11-C12 -> 400407
B14: Resultado Antes de Itens Não Operacionais | C14: =C10+C13 -> 2981484
B15: Resultado Antes dos Impostos | C15: =C14+Contas_a_Receber!O10 -> 3101484
B16: (-) Impostos sobre o Lucro (IRPJ + CSLL) | C16: =C15*(15%) -> 465222.6
B17: Lucro Líquido | C17: =C15-C16 -> 2636261.4

Sheet Cálculos
B5: Cards
B7: Receita Total | C7: Custos + Despesas | D7: Lucro Líquido | E7: Margem Líquida | F7: Saldo Final de Caixa | H7: Receita Total | I7: Custos + Despesas | J7: Lucro Líquido | K7: Margem Líquida | L7: Saldo Final
B8: =DRE_Simplificada!C6 -> 8792611 | C8: =DRE_Simplificada!C7+DRE_Simplificada!C9 -> 6211534 | D8: =DRE_Simplificada!C17 -> 2636261.4 | E8: =IFERROR(D8/B8,"") -> 0.29982691 | F8: =Fluxo_de_Caixa!E18 -> 3057402 | H8: =Tabela7[[#This Row],[Receita Total]] -> 8792611 | I8: =Tabela7[[#This Row],[Custos + Despesas]] -> 6211534 | J8: =Tabela7[[#This Row],[Lucro Líquido]] -> 2636261.4 | K8: =Tabela7[[#This Row],[Margem Líquida]] -> 0.29982691 | L8: =Tabela7[[#This Row],[Saldo Final de Caixa]] -> 3057402
B12: Gráfico Entradas x Saídas | H12: Saldo de caixa Mensal | N12: Custos e Despesas
B14: Mês | C14: Entradas | D14: Saídas | H14: Mês | I14: Saldo | N14: Mês | O14: Custo Operacional | P14: Custo Administrativo
B15: Janeiro | C15: =Fluxo_de_Caixa!C6 -> 1565367 | D15: =Fluxo_de_Caixa!D6 -> 554584 | H15: Janeiro | I15: =Fluxo_de_Caixa!E6 -> 1010783 | N15: Janeiro | O15: =Contas_a_Pagar!C18 -> 245200 | P15: =Contas_a_Pagar!C24 -> 297043
B16: Fevereiro | C16: =Fluxo_de_Caixa!C7 -> 164357 | D16: =Fluxo_de_Caixa!D7 -> 798622 | H16: Fevereiro | I16: =Fluxo_de_Caixa!E7 -> 376518 | N16: Fevereiro | O16: =Contas_a_Pagar!D18 -> 476546 | P16: =Contas_a_Pagar!D24 -> 319734
B17: Março | C17: =Fluxo_de_Caixa!C8 -> 536200 | D17: =Fluxo_de_Caixa!D8 -> 552658 | H17: Março | I17: =Fluxo_de_Caixa!E8 -> 360060 | N17: Março | O17: =Contas_a_Pagar!E18 -> 230700 | P17: =Contas_a_Pagar!E24 -> 317724
B18: Abril | C18: =Fluxo_de_Caixa!C9 -> 928680 | D18: =Fluxo_de_Caixa!D9 -> 431719 | H18: Abril | I18: =Fluxo_de_Caixa!E9 -> 857021 | N18: Abril | O18: =Tabela6[[#This Row],[Abril]] -> 115900 | P18: =Contas_a_Pagar!F24 -> 315576
B19: Maio | C19: =Fluxo_de_Caixa!C10 -> 116398 | D19: =Fluxo_de_Caixa!D10 -> 460430 | H19: Maio | I19: =Fluxo_de_Caixa!E10 -> 512989 | N19: Maio | O19: =Contas_a_Pagar!G18 -> 144400 | P19: =Contas_a_Pagar!G24 -> 315977
B20: Junho | C20: =Fluxo_de_Caixa!C11 -> 959500 | D20: =Fluxo_de_Caixa!D11 -> 463069 | H20: Junho | I20: =Fluxo_de_Caixa!E11 -> 1009420 | N20: Junho | O20: =Contas_a_Pagar!H18 -> 138060 | P20: =Contas_a_Pagar!H24 -> 300577
B21: Julho | C21: =Fluxo_de_Caixa!C12 -> 447520 | D21: =Fluxo_de_Caixa!D12 -> 482515 | H21: Julho | I21: =Fluxo_de_Caixa!E12 -> 974425 | N21: Julho | O21: =Contas_a_Pagar!I18 -> 168100 | P21: =Contas_a_Pagar!I24 -> 314181
B22: Agosto | C22: =Fluxo_de_Caixa!C13 -> 959500 | D22: =Fluxo_de_Caixa!D13 -> 495164 | H22: Agosto | I22: =Fluxo_de_Caixa!E13 -> 1438761 | N22: Agosto | O22: =Contas_a_Pagar!J18 -> 191070 | P22: =Contas_a_Pagar!J24 -> 303852
B23: Setembro | C23: =Fluxo_de_Caixa!C14 -> 928740 | D23: =Fluxo_de_Caixa!D14 -> 459223 | H23: Setembro | I23: =Fluxo_de_Caixa!E14 -> 1908278 | N23: Setembro | O23: =Contas_a_Pagar!K18 -> 157767 | P23: =Contas_a_Pagar!K24 -> 301453
B24: Outubro | C24: =Fluxo_de_Caixa!C15 -> 447760 | D24: =Fluxo_de_Caixa!D15 -> 454104 | H24: Outubro | I24: =Fluxo_de_Caixa!E15 -> 1901934 | N24: Outubro | O24: =Contas_a_Pagar!L18 -> 136448 | P24: =Tabela6[[#This Row],[Outubro]] -> 317422
B25: Novembro | C25: =Fluxo_de_Caixa!C16 -> 959740 | D25: =Fluxo_de_Caixa!D16 -> 532475 | H25: Novembro | I25: =Fluxo_de_Caixa!E16 -> 2329199 | N25: Novembro | O25: =Contas_a_Pagar!M18 -> 236587 | P25: =Contas_a_Pagar!M24 -> 295654
B26: Dezembro | C26: =Fluxo_de_Caixa!C17 -> 1300000 | D26: =Fluxo_de_Caixa!D17 -> 571797 | H26: Dezembro | I26: =Fluxo_de_Caixa!E17 -> 3057402 | N26: Dezembro | O26: =Contas_a_Pagar!N18 -> 256687 | P26: =Contas_a_Pagar!N24 -> 314876
C30: Mês | D30: Entradas | E30: Saídas | F30: Saldo | G30: Custo Operacional | H30: Custo Administrativo
C31: Janeiro | D31: =C15 -> 1565367 | E31: =D15 -> 554584 | F31: =I15 -> 1010783 | G31: =O15 -> 245200 | H31: =P15 -> 297043
C32: Fevereiro | D32: =C16 -> 164357 | E32: =D16 -> 798622 | F32: =I16 -> 376518 | G32: =O16 -> 476546 | H32: =P16 -> 319734
C33: Março | D33: =C17 -> 536200 | E33: =D17 -> 552658 | F33: =I17 -> 360060 | G33: =O17 -> 230700 | H33: =P17 -> 317724
C34: Abril | D34: =C18 -> 928680 | E34: =D18 -> 431719 | F34: =I18 -> 857021 | G34: =O18 -> 115900 | H34: =P18 -> 315576
C35: Maio | D35: =C19 -> 116398 | E35: =D19 -> 460430 | F35: =I19 -> 512989 | G35: =O19 -> 144400 | H35: =P19 -> 315977
C36: Junho | D36: =C20 -> 959500 | E36: =D20 -> 463069 | F36: =I20 -> 1009420 | G36: =O20 -> 138060 | H36: =P20 -> 300577
C37: Julho | D37: =C21 -> 447520 | E37: =D21 -> 482515 | F37: =I21 -> 974425 | G37: =O21 -> 168100 | H37: =P21 -> 314181
C38: Agosto | D38: =C22 -> 959500 | E38: =D22 -> 495164 | F38: =I22 -> 1438761 | G38: =O22 -> 191070 | H38: =P22 -> 303852
C39: Setembro | D39: =C23 -> 928740 | E39: =D23 -> 459223 | F39: =I23 -> 1908278 | G39: =O23 -> 157767 | H39: =P23 -> 301453
C40: Outubro | D40: =C24 -> 447760 | E40: =D24 -> 454104 | F40: =I24 -> 1901934 | G40: =O24 -> 136448 | H40: =P24 -> 317422
C41: Novembro | D41: =C25 -> 959740 | E41: =D25 -> 532475 | F41: =I25 -> 2329199 | G41: =O25 -> 236587 | H41: =P25 -> 295654
C42: Dezembro | D42: =C26 -> 1300000 | E42: =D26 -> 571797 | F42: =I26 -> 3057402 | G42: =O26 -> 256687 | H42: =P26 -> 314876
C46: Rótulos de Linha | D46: Soma de Entradas | E46: Soma de Saídas | J46: Rótulos de Linha | K46: Soma de Saldo
C47: Janeiro | D47: 1565367 | E47: 554584 | J47: Janeiro | K47: 1010783
C48: Fevereiro | D48: 164357 | E48: 798622 | J48: Fevereiro | K48: 376518
C49: Março | D49: 536200 | E49: 552658 | J49: Março | K49: 360060
C50: Abril | D50: 928680 | E50: 431719 | J50: Abril | K50: 857021
C51: Maio | D51: 116398 | E51: 460430 | J51: Maio | K51: 512989
C52: Junho | D52: 959500 | E52: 463069 | J52: Junho | K52: 1009420
C53: Julho | D53: 447520 | E53: 482515 | J53: Julho | K53: 974425
C54: Agosto | D54: 959500 | E54: 495164 | J54: Agosto | K54: 1438761
C55: Setembro | D55: 928740 | E55: 459223 | J55: Setembro | K55: 1908278
...

Sheet Dashboard
B24: Mês | C24: Soma de Custo Operacional | D24: Soma de Custo Administrativo | E24: Soma de Entradas | F24: Soma de Saídas | G24: Soma de Saldo
B25: Janeiro | C25: 245200 | D25: 297043 | E25: 1565367 | F25: 554584 | G25: 1010783
B26: Fevereiro | C26: 476546 | D26: 319734 | E26: 164357 | F26: 798622 | G26: 376518
B27: Março | C27: 230700 | D27: 317724 | E27: 536200 | F27: 552658 | G27: 360060
B28: Abril | C28: 115900 | D28: 315576 | E28: 928680 | F28: 431719 | G28: 857021
B29: Maio | C29: 144400 | D29: 315977 | E29: 116398 | F29: 460430 | G29: 512989
B30: Junho | C30: 138060 | D30: 300577 | E30: 959500 | F30: 463069 | G30: 1009420
B31: Julho | C31: 168100 | D31: 314181 | E31: 447520 | F31: 482515 | G31: 974425
B32: Agosto | C32: 191070 | D32: 303852 | E32: 959500 | F32: 495164 | G32: 1438761
B33: Setembro | C33: 157767 | D33: 301453 | E33: 928740 | F33: 459223 | G33: 1908278
B34: Outubro | C34: 136448 | D34: 317422 | E34: 447760 | F34: 454104 | G34: 1901934
B35: Novembro | C35: 236587 | D35: 295654 | E35: 959740 | F35: 532475 | G35: 2329199
B36: Dezembro | C36: 256687 | D36: 314876 | E36: 1300000 | F36: 571797 | G36: 3057402
B37: Total Geral | C37: 2497465 | D37: 3714069 | E37: 9313762 | F37: 6256360 | G37: 15736790
